### YamlMime:UniversalReference
api_name: []
items:
- attributes: []
  children:
  - google.cloud.bigquery.dbapi.OperationalError.with_traceback
  class: google.cloud.bigquery.dbapi.OperationalError
  fullName: google.cloud.bigquery.dbapi.OperationalError
  inheritance:
  - inheritance:
    - inheritance:
      - inheritance:
        - inheritance:
          - type: builtins.object
          type: builtins.BaseException
        type: builtins.Exception
      type: google.cloud.bigquery.dbapi.exceptions.Error
    type: google.cloud.bigquery.dbapi.exceptions.DatabaseError
  langs:
  - python
  module: google.cloud.bigquery.dbapi
  name: OperationalError
  source:
    id: OperationalError
    path: tests/testdata/gapic-combo/google/cloud/bigquery/dbapi/exceptions.py
    remote:
      branch: add_goldens
      path: tests/testdata/gapic-combo/google/cloud/bigquery/dbapi/exceptions.py
      repo: git@github.com:googleapis/sphinx-docfx-yaml.git
    startLine: 38
  summary: 'DB-API error related to the database operation.


    These errors are not necessarily under the control of the programmer.


    '
  syntax: {}
  type: class
  uid: google.cloud.bigquery.dbapi.OperationalError
- attributes: []
  class: google.cloud.bigquery.dbapi.OperationalError
  fullName: google.cloud.bigquery.dbapi.OperationalError.with_traceback
  langs:
  - python
  module: google.cloud.bigquery.dbapi
  name: with_traceback
  source:
    id: with_traceback
    path: null
    remote:
      branch: add_goldens
      path: null
      repo: git@github.com:googleapis/sphinx-docfx-yaml.git
    startLine: null
  summary: 'Exception.with_traceback(tb) --

    set self.__traceback__ to tb and return self.


    '
  syntax: {}
  type: method
  uid: google.cloud.bigquery.dbapi.OperationalError.with_traceback
references:
- fullName: google.cloud.bigquery.dbapi.OperationalError.with_traceback
  isExternal: false
  name: with_traceback
  parent: google.cloud.bigquery.dbapi.OperationalError
  uid: google.cloud.bigquery.dbapi.OperationalError.with_traceback
