### YamlMime:UniversalReference
api_name: []
items:
- attributes: []
  children:
  - google.cloud.bigquery.dbapi.Error.with_traceback
  class: google.cloud.bigquery.dbapi.Error
  fullName: google.cloud.bigquery.dbapi.Error
  inheritance:
  - inheritance:
    - inheritance:
      - type: builtins.object
      type: builtins.BaseException
    type: builtins.Exception
  langs:
  - python
  module: google.cloud.bigquery.dbapi
  name: Error
  source:
    id: Error
    path: tests/testdata/gapic-combo/google/cloud/bigquery/dbapi/exceptions.py
    remote:
      branch: add_goldens
      path: tests/testdata/gapic-combo/google/cloud/bigquery/dbapi/exceptions.py
      repo: git@github.com:googleapis/sphinx-docfx-yaml.git
    startLine: 22
  summary: 'Exception representing all non-warning DB-API errors.


    '
  syntax: {}
  type: class
  uid: google.cloud.bigquery.dbapi.Error
- attributes: []
  class: google.cloud.bigquery.dbapi.Error
  fullName: google.cloud.bigquery.dbapi.Error.with_traceback
  langs:
  - python
  module: google.cloud.bigquery.dbapi
  name: with_traceback
  source:
    id: with_traceback
    path: null
    remote:
      branch: add_goldens
      path: null
      repo: git@github.com:googleapis/sphinx-docfx-yaml.git
    startLine: null
  summary: 'Exception.with_traceback(tb) --

    set self.__traceback__ to tb and return self.


    '
  syntax: {}
  type: method
  uid: google.cloud.bigquery.dbapi.Error.with_traceback
references:
- fullName: google.cloud.bigquery.dbapi.Error.with_traceback
  isExternal: false
  name: with_traceback
  parent: google.cloud.bigquery.dbapi.Error
  uid: google.cloud.bigquery.dbapi.Error.with_traceback
